ERROR:root:Except on like!
Traceback (most recent call last):
  File "C:\Users\Manish\AppData\Local\Programs\Python\Python37-32\lib\site-packages\urllib3\connectionpool.py", line 600, in urlopen
    chunked=chunked)
  File "C:\Users\Manish\AppData\Local\Programs\Python\Python37-32\lib\site-packages\urllib3\connectionpool.py", line 384, in _make_request
    six.raise_from(e, None)
  File "<string>", line 2, in raise_from
  File "C:\Users\Manish\AppData\Local\Programs\Python\Python37-32\lib\site-packages\urllib3\connectionpool.py", line 380, in _make_request
    httplib_response = conn.getresponse()
  File "C:\Users\Manish\AppData\Local\Programs\Python\Python37-32\lib\http\client.py", line 1321, in getresponse
    response.begin()
  File "C:\Users\Manish\AppData\Local\Programs\Python\Python37-32\lib\http\client.py", line 296, in begin
    version, status, reason = self._read_status()
  File "C:\Users\Manish\AppData\Local\Programs\Python\Python37-32\lib\http\client.py", line 257, in _read_status
    line = str(self.fp.readline(_MAXLINE + 1), "iso-8859-1")
  File "C:\Users\Manish\AppData\Local\Programs\Python\Python37-32\lib\socket.py", line 589, in readinto
    return self._sock.recv_into(b)
  File "C:\Users\Manish\AppData\Local\Programs\Python\Python37-32\lib\ssl.py", line 1049, in recv_into
    return self.read(nbytes, buffer)
  File "C:\Users\Manish\AppData\Local\Programs\Python\Python37-32\lib\ssl.py", line 908, in read
    return self._sslobj.read(len, buffer)
ConnectionResetError: [WinError 10054] An existing connection was forcibly closed by the remote host

During handling of the above exception, another exception occurred:

Traceback (most recent call last):
  File "C:\Users\Manish\AppData\Local\Programs\Python\Python37-32\lib\site-packages\requests\adapters.py", line 445, in send
    timeout=timeout
  File "C:\Users\Manish\AppData\Local\Programs\Python\Python37-32\lib\site-packages\urllib3\connectionpool.py", line 638, in urlopen
    _stacktrace=sys.exc_info()[2])
  File "C:\Users\Manish\AppData\Local\Programs\Python\Python37-32\lib\site-packages\urllib3\util\retry.py", line 367, in increment
    raise six.reraise(type(error), error, _stacktrace)
  File "C:\Users\Manish\AppData\Local\Programs\Python\Python37-32\lib\site-packages\urllib3\packages\six.py", line 685, in reraise
    raise value.with_traceback(tb)
  File "C:\Users\Manish\AppData\Local\Programs\Python\Python37-32\lib\site-packages\urllib3\connectionpool.py", line 600, in urlopen
    chunked=chunked)
  File "C:\Users\Manish\AppData\Local\Programs\Python\Python37-32\lib\site-packages\urllib3\connectionpool.py", line 384, in _make_request
    six.raise_from(e, None)
  File "<string>", line 2, in raise_from
  File "C:\Users\Manish\AppData\Local\Programs\Python\Python37-32\lib\site-packages\urllib3\connectionpool.py", line 380, in _make_request
    httplib_response = conn.getresponse()
  File "C:\Users\Manish\AppData\Local\Programs\Python\Python37-32\lib\http\client.py", line 1321, in getresponse
    response.begin()
  File "C:\Users\Manish\AppData\Local\Programs\Python\Python37-32\lib\http\client.py", line 296, in begin
    version, status, reason = self._read_status()
  File "C:\Users\Manish\AppData\Local\Programs\Python\Python37-32\lib\http\client.py", line 257, in _read_status
    line = str(self.fp.readline(_MAXLINE + 1), "iso-8859-1")
  File "C:\Users\Manish\AppData\Local\Programs\Python\Python37-32\lib\socket.py", line 589, in readinto
    return self._sock.recv_into(b)
  File "C:\Users\Manish\AppData\Local\Programs\Python\Python37-32\lib\ssl.py", line 1049, in recv_into
    return self.read(nbytes, buffer)
  File "C:\Users\Manish\AppData\Local\Programs\Python\Python37-32\lib\ssl.py", line 908, in read
    return self._sslobj.read(len, buffer)
urllib3.exceptions.ProtocolError: ('Connection aborted.', ConnectionResetError(10054, 'An existing connection was forcibly closed by the remote host', None, 10054, None))

During handling of the above exception, another exception occurred:

Traceback (most recent call last):
  File "C:\Users\Manish\Desktop\Instbot\instabot.py-fix-login_error\instabot.py-fix-login_error\src\instabot.py", line 592, in like
    like = self.s.post(url_likes)
  File "C:\Users\Manish\AppData\Local\Programs\Python\Python37-32\lib\site-packages\requests\sessions.py", line 559, in post
    return self.request('POST', url, data=data, json=json, **kwargs)
  File "C:\Users\Manish\AppData\Local\Programs\Python\Python37-32\lib\site-packages\requests\sessions.py", line 512, in request
    resp = self.send(prep, **send_kwargs)
  File "C:\Users\Manish\AppData\Local\Programs\Python\Python37-32\lib\site-packages\requests\sessions.py", line 622, in send
    r = adapter.send(request, **kwargs)
  File "C:\Users\Manish\AppData\Local\Programs\Python\Python37-32\lib\site-packages\requests\adapters.py", line 495, in send
    raise ConnectionError(err, request=request)
requests.exceptions.ConnectionError: ('Connection aborted.', ConnectionResetError(10054, 'An existing connection was forcibly closed by the remote host', None, 10054, None))
